02/Apr/2018 11:20:53 DEBUG - (0.003) 
            SELECT c.relname, c.relkind
            FROM pg_catalog.pg_class c
            LEFT JOIN pg_catalog.pg_namespace n ON n.oid = c.relnamespace
            WHERE c.relkind IN ('r', 'v')
                AND n.nspname NOT IN ('pg_catalog', 'pg_toast')
                AND pg_catalog.pg_table_is_visible(c.oid); args=None
02/Apr/2018 11:20:53 DEBUG - (0.001) SELECT "django_migrations"."app", "django_migrations"."name" FROM "django_migrations"; args=()
02/Apr/2018 11:22:11 DEBUG - (0.003) SELECT "auth_user"."id", "auth_user"."password", "auth_user"."last_login", "auth_user"."is_superuser", "auth_user"."username", "auth_user"."first_name", "auth_user"."last_name", "auth_user"."email", "auth_user"."is_staff", "auth_user"."is_active", "auth_user"."date_joined" FROM "auth_user" WHERE "auth_user"."username" = 'kar'; args=('kar',)
02/Apr/2018 11:22:11 DEBUG - (0.040) INSERT INTO "auth_user" ("password", "last_login", "is_superuser", "username", "first_name", "last_name", "email", "is_staff", "is_active", "date_joined") VALUES ('pbkdf2_sha256$100000$y7gMgw45MlNy$U6Hfg0gVJL6YK0JoIBk9QzNF5BJx6QnJfI+9K7kNbxw=', NULL, false, 'kar', '8', '565', 'kartikevold99@gmail.com', false, true, '2018-04-02T11:22:11.437571'::timestamp) RETURNING "auth_user"."id"; args=('pbkdf2_sha256$100000$y7gMgw45MlNy$U6Hfg0gVJL6YK0JoIBk9QzNF5BJx6QnJfI+9K7kNbxw=', None, False, 'kar', '8', '565', 'kartikevold99@gmail.com', False, True, datetime.datetime(2018, 4, 2, 11, 22, 11, 437571))
02/Apr/2018 11:22:11 DEBUG - (0.001) SELECT "auth_user"."id", "auth_user"."password", "auth_user"."last_login", "auth_user"."is_superuser", "auth_user"."username", "auth_user"."first_name", "auth_user"."last_name", "auth_user"."email", "auth_user"."is_staff", "auth_user"."is_active", "auth_user"."date_joined" FROM "auth_user" WHERE "auth_user"."username" = 'kar'; args=('kar',)
02/Apr/2018 11:22:11 DEBUG - (0.001) SELECT (1) AS "a" FROM "django_session" WHERE "django_session"."session_key" = 'si2v56jso0x148u2uzq6r17v2cas41da' LIMIT 1; args=('si2v56jso0x148u2uzq6r17v2cas41da',)
02/Apr/2018 11:22:11 DEBUG - (0.058) INSERT INTO "django_session" ("session_key", "session_data", "expire_date") VALUES ('si2v56jso0x148u2uzq6r17v2cas41da', 'NjU1ZDY5YWFjNGY1YTgxYzBlOGFhYTU0YzY1YzNiZjFlY2FjYTcyMDp7fQ==', '2018-04-16T11:22:11.812073'::timestamp); args=('si2v56jso0x148u2uzq6r17v2cas41da', 'NjU1ZDY5YWFjNGY1YTgxYzBlOGFhYTU0YzY1YzNiZjFlY2FjYTcyMDp7fQ==', datetime.datetime(2018, 4, 16, 11, 22, 11, 812073))
02/Apr/2018 11:22:11 DEBUG - (0.002) UPDATE "auth_user" SET "last_login" = '2018-04-02T11:22:11.892989'::timestamp WHERE "auth_user"."id" = 10; args=(datetime.datetime(2018, 4, 2, 11, 22, 11, 892989), 10)
02/Apr/2018 11:22:11 DEBUG - (0.001) UPDATE "django_session" SET "session_data" = 'ODg0NmY5ODM4YzgzNDI4NGY0OTE2MGE1ZTgwNjI3NjViNzE1Y2I1YTp7Il9hdXRoX3VzZXJfaWQiOiIxMCIsIl9hdXRoX3VzZXJfYmFja2VuZCI6ImRqYW5nby5jb250cmliLmF1dGguYmFja2VuZHMuTW9kZWxCYWNrZW5kIiwiX2F1dGhfdXNlcl9oYXNoIjoiYjI3ZGY4MTU0Yjk3ZDNkNjhiNmQ2YjFhN2VmNTk5ZTQxMjhkOGQ4NyJ9', "expire_date" = '2018-04-16T11:22:11.904546'::timestamp WHERE "django_session"."session_key" = 'si2v56jso0x148u2uzq6r17v2cas41da'; args=('ODg0NmY5ODM4YzgzNDI4NGY0OTE2MGE1ZTgwNjI3NjViNzE1Y2I1YTp7Il9hdXRoX3VzZXJfaWQiOiIxMCIsIl9hdXRoX3VzZXJfYmFja2VuZCI6ImRqYW5nby5jb250cmliLmF1dGguYmFja2VuZHMuTW9kZWxCYWNrZW5kIiwiX2F1dGhfdXNlcl9oYXNoIjoiYjI3ZGY4MTU0Yjk3ZDNkNjhiNmQ2YjFhN2VmNTk5ZTQxMjhkOGQ4NyJ9', datetime.datetime(2018, 4, 16, 11, 22, 11, 904546), 'si2v56jso0x148u2uzq6r17v2cas41da')
02/Apr/2018 11:22:11 INFO - "POST /sign_up/ HTTP/1.1" 302 0
02/Apr/2018 11:22:11 DEBUG - Exception while resolving variable 'staticfiles' in template 'registration/success.html'.
Traceback (most recent call last):
  File "/home/ghostman/.local/lib/python3.6/site-packages/django/template/base.py", line 835, in _resolve_lookup
    current = current[bit]
  File "/home/ghostman/.local/lib/python3.6/site-packages/django/template/context.py", line 83, in __getitem__
    raise KeyError(key)
KeyError: 'staticfiles'

During handling of the above exception, another exception occurred:

Traceback (most recent call last):
  File "/home/ghostman/.local/lib/python3.6/site-packages/django/template/base.py", line 841, in _resolve_lookup
    if isinstance(current, BaseContext) and getattr(type(current), bit):
AttributeError: type object 'RequestContext' has no attribute 'staticfiles'

During handling of the above exception, another exception occurred:

Traceback (most recent call last):
  File "/home/ghostman/.local/lib/python3.6/site-packages/django/template/base.py", line 849, in _resolve_lookup
    current = current[int(bit)]
ValueError: invalid literal for int() with base 10: 'staticfiles'

During handling of the above exception, another exception occurred:

Traceback (most recent call last):
  File "/home/ghostman/.local/lib/python3.6/site-packages/django/template/base.py", line 856, in _resolve_lookup
    (bit, current))  # missing attribute
django.template.base.VariableDoesNotExist: Failed lookup for key [staticfiles] in [{'True': True, 'False': False, 'None': None}, {'csrf_token': <SimpleLazyObject: <function csrf.<locals>._get_val at 0x7f24bd722950>>, 'request': <WSGIRequest: GET '/register_success/'>, 'user': <SimpleLazyObject: <function AuthenticationMiddleware.process_request.<locals>.<lambda> at 0x7f24be864e18>>, 'perms': <django.contrib.auth.context_processors.PermWrapper object at 0x7f24bd78fe80>, 'messages': <django.contrib.messages.storage.fallback.FallbackStorage object at 0x7f24bd78f240>, 'DEFAULT_MESSAGE_LEVELS': {'DEBUG': 10, 'INFO': 20, 'SUCCESS': 25, 'WARNING': 30, 'ERROR': 40}}, {}]
02/Apr/2018 11:22:12 DEBUG - (0.002) SELECT "django_session"."session_key", "django_session"."session_data", "django_session"."expire_date" FROM "django_session" WHERE ("django_session"."session_key" = 'si2v56jso0x148u2uzq6r17v2cas41da' AND "django_session"."expire_date" > '2018-04-02T11:22:11.983006'::timestamp); args=('si2v56jso0x148u2uzq6r17v2cas41da', datetime.datetime(2018, 4, 2, 11, 22, 11, 983006))
02/Apr/2018 11:22:12 DEBUG - (0.001) SELECT "auth_user"."id", "auth_user"."password", "auth_user"."last_login", "auth_user"."is_superuser", "auth_user"."username", "auth_user"."first_name", "auth_user"."last_name", "auth_user"."email", "auth_user"."is_staff", "auth_user"."is_active", "auth_user"."date_joined" FROM "auth_user" WHERE "auth_user"."id" = 10; args=(10,)
02/Apr/2018 11:22:12 DEBUG - Exception while resolving variable 'staticfiles' in template 'registration/success.html'.
Traceback (most recent call last):
  File "/home/ghostman/.local/lib/python3.6/site-packages/django/template/base.py", line 835, in _resolve_lookup
    current = current[bit]
  File "/home/ghostman/.local/lib/python3.6/site-packages/django/template/context.py", line 83, in __getitem__
    raise KeyError(key)
KeyError: 'staticfiles'

During handling of the above exception, another exception occurred:

Traceback (most recent call last):
  File "/home/ghostman/.local/lib/python3.6/site-packages/django/template/base.py", line 841, in _resolve_lookup
    if isinstance(current, BaseContext) and getattr(type(current), bit):
AttributeError: type object 'RequestContext' has no attribute 'staticfiles'

During handling of the above exception, another exception occurred:

Traceback (most recent call last):
  File "/home/ghostman/.local/lib/python3.6/site-packages/django/template/base.py", line 849, in _resolve_lookup
    current = current[int(bit)]
ValueError: invalid literal for int() with base 10: 'staticfiles'

During handling of the above exception, another exception occurred:

Traceback (most recent call last):
  File "/home/ghostman/.local/lib/python3.6/site-packages/django/template/base.py", line 856, in _resolve_lookup
    (bit, current))  # missing attribute
django.template.base.VariableDoesNotExist: Failed lookup for key [staticfiles] in [{'True': True, 'False': False, 'None': None}, {'csrf_token': <SimpleLazyObject: <function csrf.<locals>._get_val at 0x7f24bd722950>>, 'request': <WSGIRequest: GET '/register_success/'>, 'user': <SimpleLazyObject: <User: kar>>, 'perms': <django.contrib.auth.context_processors.PermWrapper object at 0x7f24bd78fe80>, 'messages': <django.contrib.messages.storage.fallback.FallbackStorage object at 0x7f24bd78f240>, 'DEFAULT_MESSAGE_LEVELS': {'DEBUG': 10, 'INFO': 20, 'SUCCESS': 25, 'WARNING': 30, 'ERROR': 40}}, {}]
02/Apr/2018 11:22:12 DEBUG - Exception while resolving variable 'staticfiles' in template 'registration/success.html'.
Traceback (most recent call last):
  File "/home/ghostman/.local/lib/python3.6/site-packages/django/template/base.py", line 835, in _resolve_lookup
    current = current[bit]
  File "/home/ghostman/.local/lib/python3.6/site-packages/django/template/context.py", line 83, in __getitem__
    raise KeyError(key)
KeyError: 'staticfiles'

During handling of the above exception, another exception occurred:

Traceback (most recent call last):
  File "/home/ghostman/.local/lib/python3.6/site-packages/django/template/base.py", line 841, in _resolve_lookup
    if isinstance(current, BaseContext) and getattr(type(current), bit):
AttributeError: type object 'RequestContext' has no attribute 'staticfiles'

During handling of the above exception, another exception occurred:

Traceback (most recent call last):
  File "/home/ghostman/.local/lib/python3.6/site-packages/django/template/base.py", line 849, in _resolve_lookup
    current = current[int(bit)]
ValueError: invalid literal for int() with base 10: 'staticfiles'

During handling of the above exception, another exception occurred:

Traceback (most recent call last):
  File "/home/ghostman/.local/lib/python3.6/site-packages/django/template/base.py", line 856, in _resolve_lookup
    (bit, current))  # missing attribute
django.template.base.VariableDoesNotExist: Failed lookup for key [staticfiles] in [{'True': True, 'False': False, 'None': None}, {'csrf_token': <SimpleLazyObject: <function csrf.<locals>._get_val at 0x7f24bd722950>>, 'request': <WSGIRequest: GET '/register_success/'>, 'user': <SimpleLazyObject: <User: kar>>, 'perms': <django.contrib.auth.context_processors.PermWrapper object at 0x7f24bd78fe80>, 'messages': <django.contrib.messages.storage.fallback.FallbackStorage object at 0x7f24bd78f240>, 'DEFAULT_MESSAGE_LEVELS': {'DEBUG': 10, 'INFO': 20, 'SUCCESS': 25, 'WARNING': 30, 'ERROR': 40}}, {}]
02/Apr/2018 11:22:12 DEBUG - Exception while resolving variable 'staticfiles' in template 'registration/success.html'.
Traceback (most recent call last):
  File "/home/ghostman/.local/lib/python3.6/site-packages/django/template/base.py", line 835, in _resolve_lookup
    current = current[bit]
  File "/home/ghostman/.local/lib/python3.6/site-packages/django/template/context.py", line 83, in __getitem__
    raise KeyError(key)
KeyError: 'staticfiles'

During handling of the above exception, another exception occurred:

Traceback (most recent call last):
  File "/home/ghostman/.local/lib/python3.6/site-packages/django/template/base.py", line 841, in _resolve_lookup
    if isinstance(current, BaseContext) and getattr(type(current), bit):
AttributeError: type object 'RequestContext' has no attribute 'staticfiles'

During handling of the above exception, another exception occurred:

Traceback (most recent call last):
  File "/home/ghostman/.local/lib/python3.6/site-packages/django/template/base.py", line 849, in _resolve_lookup
    current = current[int(bit)]
ValueError: invalid literal for int() with base 10: 'staticfiles'

During handling of the above exception, another exception occurred:

Traceback (most recent call last):
  File "/home/ghostman/.local/lib/python3.6/site-packages/django/template/base.py", line 856, in _resolve_lookup
    (bit, current))  # missing attribute
django.template.base.VariableDoesNotExist: Failed lookup for key [staticfiles] in [{'True': True, 'False': False, 'None': None}, {'csrf_token': <SimpleLazyObject: <function csrf.<locals>._get_val at 0x7f24bd722950>>, 'request': <WSGIRequest: GET '/register_success/'>, 'user': <SimpleLazyObject: <User: kar>>, 'perms': <django.contrib.auth.context_processors.PermWrapper object at 0x7f24bd78fe80>, 'messages': <django.contrib.messages.storage.fallback.FallbackStorage object at 0x7f24bd78f240>, 'DEFAULT_MESSAGE_LEVELS': {'DEBUG': 10, 'INFO': 20, 'SUCCESS': 25, 'WARNING': 30, 'ERROR': 40}}, {}]
02/Apr/2018 11:22:12 DEBUG - Exception while resolving variable 'staticfiles' in template 'registration/success.html'.
Traceback (most recent call last):
  File "/home/ghostman/.local/lib/python3.6/site-packages/django/template/base.py", line 835, in _resolve_lookup
    current = current[bit]
  File "/home/ghostman/.local/lib/python3.6/site-packages/django/template/context.py", line 83, in __getitem__
    raise KeyError(key)
KeyError: 'staticfiles'

During handling of the above exception, another exception occurred:

Traceback (most recent call last):
  File "/home/ghostman/.local/lib/python3.6/site-packages/django/template/base.py", line 841, in _resolve_lookup
    if isinstance(current, BaseContext) and getattr(type(current), bit):
AttributeError: type object 'RequestContext' has no attribute 'staticfiles'

During handling of the above exception, another exception occurred:

Traceback (most recent call last):
  File "/home/ghostman/.local/lib/python3.6/site-packages/django/template/base.py", line 849, in _resolve_lookup
    current = current[int(bit)]
ValueError: invalid literal for int() with base 10: 'staticfiles'

During handling of the above exception, another exception occurred:

Traceback (most recent call last):
  File "/home/ghostman/.local/lib/python3.6/site-packages/django/template/base.py", line 856, in _resolve_lookup
    (bit, current))  # missing attribute
django.template.base.VariableDoesNotExist: Failed lookup for key [staticfiles] in [{'True': True, 'False': False, 'None': None}, {'csrf_token': <SimpleLazyObject: <function csrf.<locals>._get_val at 0x7f24bd722950>>, 'request': <WSGIRequest: GET '/register_success/'>, 'user': <SimpleLazyObject: <User: kar>>, 'perms': <django.contrib.auth.context_processors.PermWrapper object at 0x7f24bd78fe80>, 'messages': <django.contrib.messages.storage.fallback.FallbackStorage object at 0x7f24bd78f240>, 'DEFAULT_MESSAGE_LEVELS': {'DEBUG': 10, 'INFO': 20, 'SUCCESS': 25, 'WARNING': 30, 'ERROR': 40}}, {}]
02/Apr/2018 11:22:12 DEBUG - Exception while resolving variable 'staticfiles' in template 'registration/success.html'.
Traceback (most recent call last):
  File "/home/ghostman/.local/lib/python3.6/site-packages/django/template/base.py", line 835, in _resolve_lookup
    current = current[bit]
  File "/home/ghostman/.local/lib/python3.6/site-packages/django/template/context.py", line 83, in __getitem__
    raise KeyError(key)
KeyError: 'staticfiles'

During handling of the above exception, another exception occurred:

Traceback (most recent call last):
  File "/home/ghostman/.local/lib/python3.6/site-packages/django/template/base.py", line 841, in _resolve_lookup
    if isinstance(current, BaseContext) and getattr(type(current), bit):
AttributeError: type object 'RequestContext' has no attribute 'staticfiles'

During handling of the above exception, another exception occurred:

Traceback (most recent call last):
  File "/home/ghostman/.local/lib/python3.6/site-packages/django/template/base.py", line 849, in _resolve_lookup
    current = current[int(bit)]
ValueError: invalid literal for int() with base 10: 'staticfiles'

During handling of the above exception, another exception occurred:

Traceback (most recent call last):
  File "/home/ghostman/.local/lib/python3.6/site-packages/django/template/base.py", line 856, in _resolve_lookup
    (bit, current))  # missing attribute
django.template.base.VariableDoesNotExist: Failed lookup for key [staticfiles] in [{'True': True, 'False': False, 'None': None}, {'csrf_token': <SimpleLazyObject: <function csrf.<locals>._get_val at 0x7f24bd722950>>, 'request': <WSGIRequest: GET '/register_success/'>, 'user': <SimpleLazyObject: <User: kar>>, 'perms': <django.contrib.auth.context_processors.PermWrapper object at 0x7f24bd78fe80>, 'messages': <django.contrib.messages.storage.fallback.FallbackStorage object at 0x7f24bd78f240>, 'DEFAULT_MESSAGE_LEVELS': {'DEBUG': 10, 'INFO': 20, 'SUCCESS': 25, 'WARNING': 30, 'ERROR': 40}}, {}]
02/Apr/2018 11:22:12 INFO - "GET /register_success/ HTTP/1.1" 200 5005
02/Apr/2018 11:22:15 DEBUG - (0.003) SELECT "django_session"."session_key", "django_session"."session_data", "django_session"."expire_date" FROM "django_session" WHERE ("django_session"."session_key" = 'si2v56jso0x148u2uzq6r17v2cas41da' AND "django_session"."expire_date" > '2018-04-02T11:22:15.278437'::timestamp); args=('si2v56jso0x148u2uzq6r17v2cas41da', datetime.datetime(2018, 4, 2, 11, 22, 15, 278437))
02/Apr/2018 11:22:15 DEBUG - (0.001) SELECT "auth_user"."id", "auth_user"."password", "auth_user"."last_login", "auth_user"."is_superuser", "auth_user"."username", "auth_user"."first_name", "auth_user"."last_name", "auth_user"."email", "auth_user"."is_staff", "auth_user"."is_active", "auth_user"."date_joined" FROM "auth_user" WHERE "auth_user"."id" = 10; args=(10,)
02/Apr/2018 11:22:15 DEBUG - (0.001) SELECT "login_sourcing"."id", "login_sourcing"."name", "login_sourcing"."rss_url", "login_sourcing"."created_by_id", "login_sourcing"."updated_by_id", "login_sourcing"."created_on", "login_sourcing"."updated_on" FROM "login_sourcing" WHERE "login_sourcing"."created_by_id" = 10; args=(10,)
02/Apr/2018 11:22:15 INFO - "GET /home/ HTTP/1.1" 302 0
02/Apr/2018 11:22:15 DEBUG - (0.002) SELECT "django_session"."session_key", "django_session"."session_data", "django_session"."expire_date" FROM "django_session" WHERE ("django_session"."session_key" = 'si2v56jso0x148u2uzq6r17v2cas41da' AND "django_session"."expire_date" > '2018-04-02T11:22:15.311786'::timestamp); args=('si2v56jso0x148u2uzq6r17v2cas41da', datetime.datetime(2018, 4, 2, 11, 22, 15, 311786))
02/Apr/2018 11:22:15 DEBUG - (0.001) SELECT "auth_user"."id", "auth_user"."password", "auth_user"."last_login", "auth_user"."is_superuser", "auth_user"."username", "auth_user"."first_name", "auth_user"."last_name", "auth_user"."email", "auth_user"."is_staff", "auth_user"."is_active", "auth_user"."date_joined" FROM "auth_user" WHERE "auth_user"."id" = 10; args=(10,)
02/Apr/2018 11:22:15 DEBUG - Exception while resolving variable 'staticfiles' in template 'add_source.html'.
Traceback (most recent call last):
  File "/home/ghostman/.local/lib/python3.6/site-packages/django/template/base.py", line 835, in _resolve_lookup
    current = current[bit]
  File "/home/ghostman/.local/lib/python3.6/site-packages/django/template/context.py", line 83, in __getitem__
    raise KeyError(key)
KeyError: 'staticfiles'

During handling of the above exception, another exception occurred:

Traceback (most recent call last):
  File "/home/ghostman/.local/lib/python3.6/site-packages/django/template/base.py", line 841, in _resolve_lookup
    if isinstance(current, BaseContext) and getattr(type(current), bit):
AttributeError: type object 'RequestContext' has no attribute 'staticfiles'

During handling of the above exception, another exception occurred:

Traceback (most recent call last):
  File "/home/ghostman/.local/lib/python3.6/site-packages/django/template/base.py", line 849, in _resolve_lookup
    current = current[int(bit)]
ValueError: invalid literal for int() with base 10: 'staticfiles'

During handling of the above exception, another exception occurred:

Traceback (most recent call last):
  File "/home/ghostman/.local/lib/python3.6/site-packages/django/template/base.py", line 856, in _resolve_lookup
    (bit, current))  # missing attribute
django.template.base.VariableDoesNotExist: Failed lookup for key [staticfiles] in [{'True': True, 'False': False, 'None': None}, {'csrf_token': <SimpleLazyObject: <function csrf.<locals>._get_val at 0x7f24bd741e18>>, 'request': <WSGIRequest: GET '/add_source/'>, 'user': <SimpleLazyObject: <User: kar>>, 'perms': <django.contrib.auth.context_processors.PermWrapper object at 0x7f24bd738208>, 'messages': <django.contrib.messages.storage.fallback.FallbackStorage object at 0x7f24bd7385c0>, 'DEFAULT_MESSAGE_LEVELS': {'DEBUG': 10, 'INFO': 20, 'SUCCESS': 25, 'WARNING': 30, 'ERROR': 40}}, {}, {'form': <AddSource bound=False, valid=Unknown, fields=(name;rss_url)>}]
02/Apr/2018 11:22:15 DEBUG - Exception while resolving variable 'staticfiles' in template 'add_source.html'.
Traceback (most recent call last):
  File "/home/ghostman/.local/lib/python3.6/site-packages/django/template/base.py", line 835, in _resolve_lookup
    current = current[bit]
  File "/home/ghostman/.local/lib/python3.6/site-packages/django/template/context.py", line 83, in __getitem__
    raise KeyError(key)
KeyError: 'staticfiles'

During handling of the above exception, another exception occurred:

Traceback (most recent call last):
  File "/home/ghostman/.local/lib/python3.6/site-packages/django/template/base.py", line 841, in _resolve_lookup
    if isinstance(current, BaseContext) and getattr(type(current), bit):
AttributeError: type object 'RequestContext' has no attribute 'staticfiles'

During handling of the above exception, another exception occurred:

Traceback (most recent call last):
  File "/home/ghostman/.local/lib/python3.6/site-packages/django/template/base.py", line 849, in _resolve_lookup
    current = current[int(bit)]
ValueError: invalid literal for int() with base 10: 'staticfiles'

During handling of the above exception, another exception occurred:

Traceback (most recent call last):
  File "/home/ghostman/.local/lib/python3.6/site-packages/django/template/base.py", line 856, in _resolve_lookup
    (bit, current))  # missing attribute
django.template.base.VariableDoesNotExist: Failed lookup for key [staticfiles] in [{'True': True, 'False': False, 'None': None}, {'csrf_token': <SimpleLazyObject: 'RzmWZ66y21Y0BAVwJ0Qw1R8eMu0rH1uRPmwPNWjHjhsTAOExYp6WnVzd0XwiUaSu'>, 'request': <WSGIRequest: GET '/add_source/'>, 'user': <SimpleLazyObject: <User: kar>>, 'perms': <django.contrib.auth.context_processors.PermWrapper object at 0x7f24bd738208>, 'messages': <django.contrib.messages.storage.fallback.FallbackStorage object at 0x7f24bd7385c0>, 'DEFAULT_MESSAGE_LEVELS': {'DEBUG': 10, 'INFO': 20, 'SUCCESS': 25, 'WARNING': 30, 'ERROR': 40}}, {}, {'form': <AddSource bound=False, valid=False, fields=(name;rss_url)>}]
02/Apr/2018 11:22:15 DEBUG - Exception while resolving variable 'staticfiles' in template 'add_source.html'.
Traceback (most recent call last):
  File "/home/ghostman/.local/lib/python3.6/site-packages/django/template/base.py", line 835, in _resolve_lookup
    current = current[bit]
  File "/home/ghostman/.local/lib/python3.6/site-packages/django/template/context.py", line 83, in __getitem__
    raise KeyError(key)
KeyError: 'staticfiles'

During handling of the above exception, another exception occurred:

Traceback (most recent call last):
  File "/home/ghostman/.local/lib/python3.6/site-packages/django/template/base.py", line 841, in _resolve_lookup
    if isinstance(current, BaseContext) and getattr(type(current), bit):
AttributeError: type object 'RequestContext' has no attribute 'staticfiles'

During handling of the above exception, another exception occurred:

Traceback (most recent call last):
  File "/home/ghostman/.local/lib/python3.6/site-packages/django/template/base.py", line 849, in _resolve_lookup
    current = current[int(bit)]
ValueError: invalid literal for int() with base 10: 'staticfiles'

During handling of the above exception, another exception occurred:

Traceback (most recent call last):
  File "/home/ghostman/.local/lib/python3.6/site-packages/django/template/base.py", line 856, in _resolve_lookup
    (bit, current))  # missing attribute
django.template.base.VariableDoesNotExist: Failed lookup for key [staticfiles] in [{'True': True, 'False': False, 'None': None}, {'csrf_token': <SimpleLazyObject: 'RzmWZ66y21Y0BAVwJ0Qw1R8eMu0rH1uRPmwPNWjHjhsTAOExYp6WnVzd0XwiUaSu'>, 'request': <WSGIRequest: GET '/add_source/'>, 'user': <SimpleLazyObject: <User: kar>>, 'perms': <django.contrib.auth.context_processors.PermWrapper object at 0x7f24bd738208>, 'messages': <django.contrib.messages.storage.fallback.FallbackStorage object at 0x7f24bd7385c0>, 'DEFAULT_MESSAGE_LEVELS': {'DEBUG': 10, 'INFO': 20, 'SUCCESS': 25, 'WARNING': 30, 'ERROR': 40}}, {}, {'form': <AddSource bound=False, valid=False, fields=(name;rss_url)>}]
02/Apr/2018 11:22:15 DEBUG - Exception while resolving variable 'staticfiles' in template 'add_source.html'.
Traceback (most recent call last):
  File "/home/ghostman/.local/lib/python3.6/site-packages/django/template/base.py", line 835, in _resolve_lookup
    current = current[bit]
  File "/home/ghostman/.local/lib/python3.6/site-packages/django/template/context.py", line 83, in __getitem__
    raise KeyError(key)
KeyError: 'staticfiles'

During handling of the above exception, another exception occurred:

Traceback (most recent call last):
  File "/home/ghostman/.local/lib/python3.6/site-packages/django/template/base.py", line 841, in _resolve_lookup
    if isinstance(current, BaseContext) and getattr(type(current), bit):
AttributeError: type object 'RequestContext' has no attribute 'staticfiles'

During handling of the above exception, another exception occurred:

Traceback (most recent call last):
  File "/home/ghostman/.local/lib/python3.6/site-packages/django/template/base.py", line 849, in _resolve_lookup
    current = current[int(bit)]
ValueError: invalid literal for int() with base 10: 'staticfiles'

During handling of the above exception, another exception occurred:

Traceback (most recent call last):
  File "/home/ghostman/.local/lib/python3.6/site-packages/django/template/base.py", line 856, in _resolve_lookup
    (bit, current))  # missing attribute
django.template.base.VariableDoesNotExist: Failed lookup for key [staticfiles] in [{'True': True, 'False': False, 'None': None}, {'csrf_token': <SimpleLazyObject: 'RzmWZ66y21Y0BAVwJ0Qw1R8eMu0rH1uRPmwPNWjHjhsTAOExYp6WnVzd0XwiUaSu'>, 'request': <WSGIRequest: GET '/add_source/'>, 'user': <SimpleLazyObject: <User: kar>>, 'perms': <django.contrib.auth.context_processors.PermWrapper object at 0x7f24bd738208>, 'messages': <django.contrib.messages.storage.fallback.FallbackStorage object at 0x7f24bd7385c0>, 'DEFAULT_MESSAGE_LEVELS': {'DEBUG': 10, 'INFO': 20, 'SUCCESS': 25, 'WARNING': 30, 'ERROR': 40}}, {}, {'form': <AddSource bound=False, valid=False, fields=(name;rss_url)>}]
02/Apr/2018 11:22:15 DEBUG - Exception while resolving variable 'staticfiles' in template 'add_source.html'.
Traceback (most recent call last):
  File "/home/ghostman/.local/lib/python3.6/site-packages/django/template/base.py", line 835, in _resolve_lookup
    current = current[bit]
  File "/home/ghostman/.local/lib/python3.6/site-packages/django/template/context.py", line 83, in __getitem__
    raise KeyError(key)
KeyError: 'staticfiles'

During handling of the above exception, another exception occurred:

Traceback (most recent call last):
  File "/home/ghostman/.local/lib/python3.6/site-packages/django/template/base.py", line 841, in _resolve_lookup
    if isinstance(current, BaseContext) and getattr(type(current), bit):
AttributeError: type object 'RequestContext' has no attribute 'staticfiles'

During handling of the above exception, another exception occurred:

Traceback (most recent call last):
  File "/home/ghostman/.local/lib/python3.6/site-packages/django/template/base.py", line 849, in _resolve_lookup
    current = current[int(bit)]
ValueError: invalid literal for int() with base 10: 'staticfiles'

During handling of the above exception, another exception occurred:

Traceback (most recent call last):
  File "/home/ghostman/.local/lib/python3.6/site-packages/django/template/base.py", line 856, in _resolve_lookup
    (bit, current))  # missing attribute
django.template.base.VariableDoesNotExist: Failed lookup for key [staticfiles] in [{'True': True, 'False': False, 'None': None}, {'csrf_token': <SimpleLazyObject: 'RzmWZ66y21Y0BAVwJ0Qw1R8eMu0rH1uRPmwPNWjHjhsTAOExYp6WnVzd0XwiUaSu'>, 'request': <WSGIRequest: GET '/add_source/'>, 'user': <SimpleLazyObject: <User: kar>>, 'perms': <django.contrib.auth.context_processors.PermWrapper object at 0x7f24bd738208>, 'messages': <django.contrib.messages.storage.fallback.FallbackStorage object at 0x7f24bd7385c0>, 'DEFAULT_MESSAGE_LEVELS': {'DEBUG': 10, 'INFO': 20, 'SUCCESS': 25, 'WARNING': 30, 'ERROR': 40}}, {}, {'form': <AddSource bound=False, valid=False, fields=(name;rss_url)>}]
02/Apr/2018 11:22:15 DEBUG - Exception while resolving variable 'staticfiles' in template 'add_source.html'.
Traceback (most recent call last):
  File "/home/ghostman/.local/lib/python3.6/site-packages/django/template/base.py", line 835, in _resolve_lookup
    current = current[bit]
  File "/home/ghostman/.local/lib/python3.6/site-packages/django/template/context.py", line 83, in __getitem__
    raise KeyError(key)
KeyError: 'staticfiles'

During handling of the above exception, another exception occurred:

Traceback (most recent call last):
  File "/home/ghostman/.local/lib/python3.6/site-packages/django/template/base.py", line 841, in _resolve_lookup
    if isinstance(current, BaseContext) and getattr(type(current), bit):
AttributeError: type object 'RequestContext' has no attribute 'staticfiles'

During handling of the above exception, another exception occurred:

Traceback (most recent call last):
  File "/home/ghostman/.local/lib/python3.6/site-packages/django/template/base.py", line 849, in _resolve_lookup
    current = current[int(bit)]
ValueError: invalid literal for int() with base 10: 'staticfiles'

During handling of the above exception, another exception occurred:

Traceback (most recent call last):
  File "/home/ghostman/.local/lib/python3.6/site-packages/django/template/base.py", line 856, in _resolve_lookup
    (bit, current))  # missing attribute
django.template.base.VariableDoesNotExist: Failed lookup for key [staticfiles] in [{'True': True, 'False': False, 'None': None}, {'csrf_token': <SimpleLazyObject: 'RzmWZ66y21Y0BAVwJ0Qw1R8eMu0rH1uRPmwPNWjHjhsTAOExYp6WnVzd0XwiUaSu'>, 'request': <WSGIRequest: GET '/add_source/'>, 'user': <SimpleLazyObject: <User: kar>>, 'perms': <django.contrib.auth.context_processors.PermWrapper object at 0x7f24bd738208>, 'messages': <django.contrib.messages.storage.fallback.FallbackStorage object at 0x7f24bd7385c0>, 'DEFAULT_MESSAGE_LEVELS': {'DEBUG': 10, 'INFO': 20, 'SUCCESS': 25, 'WARNING': 30, 'ERROR': 40}}, {}, {'form': <AddSource bound=False, valid=False, fields=(name;rss_url)>}]
02/Apr/2018 11:22:15 INFO - "GET /add_source/ HTTP/1.1" 200 6089
02/Apr/2018 11:22:19 DEBUG - (0.002) SELECT "django_session"."session_key", "django_session"."session_data", "django_session"."expire_date" FROM "django_session" WHERE ("django_session"."session_key" = 'si2v56jso0x148u2uzq6r17v2cas41da' AND "django_session"."expire_date" > '2018-04-02T11:22:19.694524'::timestamp); args=('si2v56jso0x148u2uzq6r17v2cas41da', datetime.datetime(2018, 4, 2, 11, 22, 19, 694524))
02/Apr/2018 11:22:19 DEBUG - (0.001) SELECT "auth_user"."id", "auth_user"."password", "auth_user"."last_login", "auth_user"."is_superuser", "auth_user"."username", "auth_user"."first_name", "auth_user"."last_name", "auth_user"."email", "auth_user"."is_staff", "auth_user"."is_active", "auth_user"."date_joined" FROM "auth_user" WHERE "auth_user"."id" = 10; args=(10,)
02/Apr/2018 11:22:19 DEBUG - (0.000) SELECT "django_session"."session_key", "django_session"."session_data", "django_session"."expire_date" FROM "django_session" WHERE "django_session"."session_key" = 'si2v56jso0x148u2uzq6r17v2cas41da'; args=('si2v56jso0x148u2uzq6r17v2cas41da',)
02/Apr/2018 11:22:19 DEBUG - (0.001) DELETE FROM "django_session" WHERE "django_session"."session_key" IN ('si2v56jso0x148u2uzq6r17v2cas41da'); args=('si2v56jso0x148u2uzq6r17v2cas41da',)
02/Apr/2018 11:22:19 INFO - "GET /logout/ HTTP/1.1" 302 0
02/Apr/2018 11:22:19 DEBUG - Exception while resolving variable 'staticfiles' in template 'registration/login.html'.
Traceback (most recent call last):
  File "/home/ghostman/.local/lib/python3.6/site-packages/django/template/base.py", line 835, in _resolve_lookup
    current = current[bit]
  File "/home/ghostman/.local/lib/python3.6/site-packages/django/template/context.py", line 83, in __getitem__
    raise KeyError(key)
KeyError: 'staticfiles'

During handling of the above exception, another exception occurred:

Traceback (most recent call last):
  File "/home/ghostman/.local/lib/python3.6/site-packages/django/template/base.py", line 841, in _resolve_lookup
    if isinstance(current, BaseContext) and getattr(type(current), bit):
AttributeError: type object 'RequestContext' has no attribute 'staticfiles'

During handling of the above exception, another exception occurred:

Traceback (most recent call last):
  File "/home/ghostman/.local/lib/python3.6/site-packages/django/template/base.py", line 849, in _resolve_lookup
    current = current[int(bit)]
ValueError: invalid literal for int() with base 10: 'staticfiles'

During handling of the above exception, another exception occurred:

Traceback (most recent call last):
  File "/home/ghostman/.local/lib/python3.6/site-packages/django/template/base.py", line 856, in _resolve_lookup
    (bit, current))  # missing attribute
django.template.base.VariableDoesNotExist: Failed lookup for key [staticfiles] in [{'True': True, 'False': False, 'None': None}, {'csrf_token': <SimpleLazyObject: <function csrf.<locals>._get_val at 0x7f24bd7340d0>>, 'request': <WSGIRequest: GET '/'>, 'user': <SimpleLazyObject: <function AuthenticationMiddleware.process_request.<locals>.<lambda> at 0x7f24be864e18>>, 'perms': <django.contrib.auth.context_processors.PermWrapper object at 0x7f24bd78ff28>, 'messages': <django.contrib.messages.storage.fallback.FallbackStorage object at 0x7f24bd72da20>, 'DEFAULT_MESSAGE_LEVELS': {'DEBUG': 10, 'INFO': 20, 'SUCCESS': 25, 'WARNING': 30, 'ERROR': 40}}, {}, {'form': <CustomAuthForm bound=False, valid=Unknown, fields=(username;password)>, 'view': <django.contrib.auth.views.LoginView object at 0x7f24bd72dba8>, 'next': '', 'site': <django.contrib.sites.requests.RequestSite object at 0x7f24bd78ff98>, 'site_name': '127.0.0.1:8000'}]
02/Apr/2018 11:22:19 DEBUG - Exception while resolving variable 'staticfiles' in template 'registration/login.html'.
Traceback (most recent call last):
  File "/home/ghostman/.local/lib/python3.6/site-packages/django/template/base.py", line 835, in _resolve_lookup
    current = current[bit]
  File "/home/ghostman/.local/lib/python3.6/site-packages/django/template/context.py", line 83, in __getitem__
    raise KeyError(key)
KeyError: 'staticfiles'

During handling of the above exception, another exception occurred:

Traceback (most recent call last):
  File "/home/ghostman/.local/lib/python3.6/site-packages/django/template/base.py", line 841, in _resolve_lookup
    if isinstance(current, BaseContext) and getattr(type(current), bit):
AttributeError: type object 'RequestContext' has no attribute 'staticfiles'

During handling of the above exception, another exception occurred:

Traceback (most recent call last):
  File "/home/ghostman/.local/lib/python3.6/site-packages/django/template/base.py", line 849, in _resolve_lookup
    current = current[int(bit)]
ValueError: invalid literal for int() with base 10: 'staticfiles'

During handling of the above exception, another exception occurred:

Traceback (most recent call last):
  File "/home/ghostman/.local/lib/python3.6/site-packages/django/template/base.py", line 856, in _resolve_lookup
    (bit, current))  # missing attribute
django.template.base.VariableDoesNotExist: Failed lookup for key [staticfiles] in [{'True': True, 'False': False, 'None': None}, {'csrf_token': <SimpleLazyObject: 'a5FikDjphZi4H1ehBJrRuDwlz8XoKTvY8SPb8twyyfMXGfXiQ8HhQHXkNBtfX2TB'>, 'request': <WSGIRequest: GET '/'>, 'user': <SimpleLazyObject: <django.contrib.auth.models.AnonymousUser object at 0x7f24bd4beb38>>, 'perms': <django.contrib.auth.context_processors.PermWrapper object at 0x7f24bd78ff28>, 'messages': <django.contrib.messages.storage.fallback.FallbackStorage object at 0x7f24bd72da20>, 'DEFAULT_MESSAGE_LEVELS': {'DEBUG': 10, 'INFO': 20, 'SUCCESS': 25, 'WARNING': 30, 'ERROR': 40}}, {}, {'form': <CustomAuthForm bound=False, valid=False, fields=(username;password)>, 'view': <django.contrib.auth.views.LoginView object at 0x7f24bd72dba8>, 'next': '', 'site': <django.contrib.sites.requests.RequestSite object at 0x7f24bd78ff98>, 'site_name': '127.0.0.1:8000'}]
02/Apr/2018 11:22:19 DEBUG - Exception while resolving variable 'staticfiles' in template 'registration/login.html'.
Traceback (most recent call last):
  File "/home/ghostman/.local/lib/python3.6/site-packages/django/template/base.py", line 835, in _resolve_lookup
    current = current[bit]
  File "/home/ghostman/.local/lib/python3.6/site-packages/django/template/context.py", line 83, in __getitem__
    raise KeyError(key)
KeyError: 'staticfiles'

During handling of the above exception, another exception occurred:

Traceback (most recent call last):
  File "/home/ghostman/.local/lib/python3.6/site-packages/django/template/base.py", line 841, in _resolve_lookup
    if isinstance(current, BaseContext) and getattr(type(current), bit):
AttributeError: type object 'RequestContext' has no attribute 'staticfiles'

During handling of the above exception, another exception occurred:

Traceback (most recent call last):
  File "/home/ghostman/.local/lib/python3.6/site-packages/django/template/base.py", line 849, in _resolve_lookup
    current = current[int(bit)]
ValueError: invalid literal for int() with base 10: 'staticfiles'

During handling of the above exception, another exception occurred:

Traceback (most recent call last):
  File "/home/ghostman/.local/lib/python3.6/site-packages/django/template/base.py", line 856, in _resolve_lookup
    (bit, current))  # missing attribute
django.template.base.VariableDoesNotExist: Failed lookup for key [staticfiles] in [{'True': True, 'False': False, 'None': None}, {'csrf_token': <SimpleLazyObject: 'a5FikDjphZi4H1ehBJrRuDwlz8XoKTvY8SPb8twyyfMXGfXiQ8HhQHXkNBtfX2TB'>, 'request': <WSGIRequest: GET '/'>, 'user': <SimpleLazyObject: <django.contrib.auth.models.AnonymousUser object at 0x7f24bd4beb38>>, 'perms': <django.contrib.auth.context_processors.PermWrapper object at 0x7f24bd78ff28>, 'messages': <django.contrib.messages.storage.fallback.FallbackStorage object at 0x7f24bd72da20>, 'DEFAULT_MESSAGE_LEVELS': {'DEBUG': 10, 'INFO': 20, 'SUCCESS': 25, 'WARNING': 30, 'ERROR': 40}}, {}, {'form': <CustomAuthForm bound=False, valid=False, fields=(username;password)>, 'view': <django.contrib.auth.views.LoginView object at 0x7f24bd72dba8>, 'next': '', 'site': <django.contrib.sites.requests.RequestSite object at 0x7f24bd78ff98>, 'site_name': '127.0.0.1:8000'}]
02/Apr/2018 11:22:19 DEBUG - Exception while resolving variable 'staticfiles' in template 'registration/login.html'.
Traceback (most recent call last):
  File "/home/ghostman/.local/lib/python3.6/site-packages/django/template/base.py", line 835, in _resolve_lookup
    current = current[bit]
  File "/home/ghostman/.local/lib/python3.6/site-packages/django/template/context.py", line 83, in __getitem__
    raise KeyError(key)
KeyError: 'staticfiles'

During handling of the above exception, another exception occurred:

Traceback (most recent call last):
  File "/home/ghostman/.local/lib/python3.6/site-packages/django/template/base.py", line 841, in _resolve_lookup
    if isinstance(current, BaseContext) and getattr(type(current), bit):
AttributeError: type object 'RequestContext' has no attribute 'staticfiles'

During handling of the above exception, another exception occurred:

Traceback (most recent call last):
  File "/home/ghostman/.local/lib/python3.6/site-packages/django/template/base.py", line 849, in _resolve_lookup
    current = current[int(bit)]
ValueError: invalid literal for int() with base 10: 'staticfiles'

During handling of the above exception, another exception occurred:

Traceback (most recent call last):
  File "/home/ghostman/.local/lib/python3.6/site-packages/django/template/base.py", line 856, in _resolve_lookup
    (bit, current))  # missing attribute
django.template.base.VariableDoesNotExist: Failed lookup for key [staticfiles] in [{'True': True, 'False': False, 'None': None}, {'csrf_token': <SimpleLazyObject: 'a5FikDjphZi4H1ehBJrRuDwlz8XoKTvY8SPb8twyyfMXGfXiQ8HhQHXkNBtfX2TB'>, 'request': <WSGIRequest: GET '/'>, 'user': <SimpleLazyObject: <django.contrib.auth.models.AnonymousUser object at 0x7f24bd4beb38>>, 'perms': <django.contrib.auth.context_processors.PermWrapper object at 0x7f24bd78ff28>, 'messages': <django.contrib.messages.storage.fallback.FallbackStorage object at 0x7f24bd72da20>, 'DEFAULT_MESSAGE_LEVELS': {'DEBUG': 10, 'INFO': 20, 'SUCCESS': 25, 'WARNING': 30, 'ERROR': 40}}, {}, {'form': <CustomAuthForm bound=False, valid=False, fields=(username;password)>, 'view': <django.contrib.auth.views.LoginView object at 0x7f24bd72dba8>, 'next': '', 'site': <django.contrib.sites.requests.RequestSite object at 0x7f24bd78ff98>, 'site_name': '127.0.0.1:8000'}]
02/Apr/2018 11:22:19 DEBUG - Exception while resolving variable 'staticfiles' in template 'registration/login.html'.
Traceback (most recent call last):
  File "/home/ghostman/.local/lib/python3.6/site-packages/django/template/base.py", line 835, in _resolve_lookup
    current = current[bit]
  File "/home/ghostman/.local/lib/python3.6/site-packages/django/template/context.py", line 83, in __getitem__
    raise KeyError(key)
KeyError: 'staticfiles'

During handling of the above exception, another exception occurred:

Traceback (most recent call last):
  File "/home/ghostman/.local/lib/python3.6/site-packages/django/template/base.py", line 841, in _resolve_lookup
    if isinstance(current, BaseContext) and getattr(type(current), bit):
AttributeError: type object 'RequestContext' has no attribute 'staticfiles'

During handling of the above exception, another exception occurred:

Traceback (most recent call last):
  File "/home/ghostman/.local/lib/python3.6/site-packages/django/template/base.py", line 849, in _resolve_lookup
    current = current[int(bit)]
ValueError: invalid literal for int() with base 10: 'staticfiles'

During handling of the above exception, another exception occurred:

Traceback (most recent call last):
  File "/home/ghostman/.local/lib/python3.6/site-packages/django/template/base.py", line 856, in _resolve_lookup
    (bit, current))  # missing attribute
django.template.base.VariableDoesNotExist: Failed lookup for key [staticfiles] in [{'True': True, 'False': False, 'None': None}, {'csrf_token': <SimpleLazyObject: 'a5FikDjphZi4H1ehBJrRuDwlz8XoKTvY8SPb8twyyfMXGfXiQ8HhQHXkNBtfX2TB'>, 'request': <WSGIRequest: GET '/'>, 'user': <SimpleLazyObject: <django.contrib.auth.models.AnonymousUser object at 0x7f24bd4beb38>>, 'perms': <django.contrib.auth.context_processors.PermWrapper object at 0x7f24bd78ff28>, 'messages': <django.contrib.messages.storage.fallback.FallbackStorage object at 0x7f24bd72da20>, 'DEFAULT_MESSAGE_LEVELS': {'DEBUG': 10, 'INFO': 20, 'SUCCESS': 25, 'WARNING': 30, 'ERROR': 40}}, {}, {'form': <CustomAuthForm bound=False, valid=False, fields=(username;password)>, 'view': <django.contrib.auth.views.LoginView object at 0x7f24bd72dba8>, 'next': '', 'site': <django.contrib.sites.requests.RequestSite object at 0x7f24bd78ff98>, 'site_name': '127.0.0.1:8000'}]
02/Apr/2018 11:22:19 DEBUG - Exception while resolving variable 'staticfiles' in template 'registration/login.html'.
Traceback (most recent call last):
  File "/home/ghostman/.local/lib/python3.6/site-packages/django/template/base.py", line 835, in _resolve_lookup
    current = current[bit]
  File "/home/ghostman/.local/lib/python3.6/site-packages/django/template/context.py", line 83, in __getitem__
    raise KeyError(key)
KeyError: 'staticfiles'

During handling of the above exception, another exception occurred:

Traceback (most recent call last):
  File "/home/ghostman/.local/lib/python3.6/site-packages/django/template/base.py", line 841, in _resolve_lookup
    if isinstance(current, BaseContext) and getattr(type(current), bit):
AttributeError: type object 'RequestContext' has no attribute 'staticfiles'

During handling of the above exception, another exception occurred:

Traceback (most recent call last):
  File "/home/ghostman/.local/lib/python3.6/site-packages/django/template/base.py", line 849, in _resolve_lookup
    current = current[int(bit)]
ValueError: invalid literal for int() with base 10: 'staticfiles'

During handling of the above exception, another exception occurred:

Traceback (most recent call last):
  File "/home/ghostman/.local/lib/python3.6/site-packages/django/template/base.py", line 856, in _resolve_lookup
    (bit, current))  # missing attribute
django.template.base.VariableDoesNotExist: Failed lookup for key [staticfiles] in [{'True': True, 'False': False, 'None': None}, {'csrf_token': <SimpleLazyObject: 'a5FikDjphZi4H1ehBJrRuDwlz8XoKTvY8SPb8twyyfMXGfXiQ8HhQHXkNBtfX2TB'>, 'request': <WSGIRequest: GET '/'>, 'user': <SimpleLazyObject: <django.contrib.auth.models.AnonymousUser object at 0x7f24bd4beb38>>, 'perms': <django.contrib.auth.context_processors.PermWrapper object at 0x7f24bd78ff28>, 'messages': <django.contrib.messages.storage.fallback.FallbackStorage object at 0x7f24bd72da20>, 'DEFAULT_MESSAGE_LEVELS': {'DEBUG': 10, 'INFO': 20, 'SUCCESS': 25, 'WARNING': 30, 'ERROR': 40}}, {}, {'form': <CustomAuthForm bound=False, valid=False, fields=(username;password)>, 'view': <django.contrib.auth.views.LoginView object at 0x7f24bd72dba8>, 'next': '', 'site': <django.contrib.sites.requests.RequestSite object at 0x7f24bd78ff98>, 'site_name': '127.0.0.1:8000'}]
02/Apr/2018 11:22:19 INFO - "GET / HTTP/1.1" 200 5214
